Workbook

Sheet Definitioner
A1: Projekt/plats/samhälle
A2: Projektnamn
A4: Parameter | B4: Definition | C4: Mätmetod
A5: Rent | B5: Renhållning av allmänna ytor och återvinning | C5: Enkät (60%) + Städfrekvens (20%) + Tömning (10%) + Återvinning (10%)
A6: Möjlighet att mötas | B6: Tillgång till öppna mötesplatser | C6: Avstånd till torg (40%), park (40%), fritidsgård (20%)
A7: Igenkänning | B7: Stabilitet i boendet | C7: Omflyttningsfrekvens + andel 2:a-handskontrakt
A8: Trygghet | B8: Faktisk och upplevd trygghet | C8: Anmälda brott/1000 inv (70%) + Enkät (30%)
A9: Service | B9: Tillgänglighet till service | C9: Avstånd till post, shopping, återvinning, skola
A10: Utbildning | B10: Tillgång till högre utbildning | C10: Restid till närmaste lärosäte
A11: Barfota | B11: Tillgång till grönytor | C11: Andel grönyta inom 2km radie + kvalitetsindex
A12: Föreningsliv | B12: Tillgång till föreningslokaler | C12: Avstånd (50%) + antal lokaler (50%)
A13: Leveranser | B13: Möjlighet till hemleveranser | C13: Antal leverantörer + typ av leveranser
A14: Variation gator | B14: Mix av olika vägtyper | C14: Fördelning mellan olika vägklasser
A15: Livsmedel | B15: Tillgång till matbutiker | C15: Avstånd till närbutik (60%) + stormarknad (40%)
... A34: Blandad bebyggelse | B34: Aktivitet över dygnet | C34: Dygnsfördelning (50%) + användargrupper (50%)

Sheet Indata
A1: Parameter | B1: Delparameter | C1: Råvärde | D1: Enhet | E1: Kommentar
A2: Rent | B2: Enkät | C2: 4 | D2: Skala 1-5 | E2: Upplevs det som rent?
A3: Rent | B3: Städfrekvens | C3: 4 | D3: Dagar/vecka | E3: Hur ofta städas gatorna?
A4: Rent | B4: Tömning | C4: 7 | D4: ggr/vecka | E4: Hur ofta töms papperskorgar?
A5: Rent | B5: Återvinning | C5: 300 | D5: Avstånd till ÅV-station | E5: Avstånd till närmaste återvinningsstation
A6: Möjlighet att mötas | B6: Torg | C6: 200 | D6: Meter | E6: Avstånd till närmaste torg
A7: Möjlighet att mötas | B7: Park | C7: 200 | D7: Meter | E7: Avstånd till närmaste park
A8: Möjlighet att mötas | B8: Fritidsgård | C8: 800 | D8: Meter | E8: Avstånd till närmaste fritidsgård
A9: Igenkänning | B9: Nyinflyttning | C9: 12 | D9: Procent/år | E9: Årlig nyinfflyttning
A10: Igenkänning | B10: Andrahand | C10: 8 | D10: Procent | E10: Andel andrahandskontrakt
A11: Trygghet | B11: Brott | C11: 45 | D11: Antal/år | E11: Anmälda brott i lokalsamhället/mikrosamhället
A12: Trygghet | B12: Enkät | C12: 3 | D12: Skala 1-5 | E12: Upplevd trygghet
A13: Service | B13: Post | C13: 450 | D13: Meter | E13: Avstånd till närmaste postombud
... A68: Blandad bebyggelse | B68: Användargrupper | C68: 4 | D68: Antal | E68: Antal åldersgrupper som deltar i aktiviteter, 0-15, 15-25, 25-40, 40-60, 60-75, 75+

Sheet Beräkningar
A1: Parameter | B1: Delparameter | C1: Råvärde | D1: Vikt(%) | E1: Max/referensvärde | F1: Optimalt värde | G1: Logik | H1: Normaliserat värde | I1: Viktat värde | J1: Totalt | K1: Parameter
A2: =Indata!A2 -> Rent | B2: =Indata!B2 -> Enkät | C2: =Indata!C2 -> 4 | D2: 0.6 | E2: 5 | G2: Max | H2: =IF(G2="Max",C2/E2,IF(G2="Min",(E2-C2)/E2,IF(G2="Opt",(1-ABS(C2-F2)/(E2-F2)),"Fel i logik"))) -> 0.8 | I2: =H2*D2 -> 0.48 | J2: =SUM(I2:I5) -> 0.75571429 | K2: =A2 -> Rent
A3: =Indata!A3 -> Rent | B3: =Indata!B3 -> Städfrekvens | C3: =Indata!C3 -> 4 | D3: 0.2 | E3: 7 | G3: Max | H3: =IF(G3="Max",C3/E3,IF(G3="Min",(E3-C3)/E3,IF(G3="Opt",(1-ABS(C3-F3)/(E3-F3)),"Fel i logik"))) -> 0.57142857 | I3: =H3*D3 -> 0.11428571
A4: =Indata!A4 -> Rent | B4: =Indata!B4 -> Tömning | C4: =Indata!C4 -> 7 | D4: 0.1 | E4: 7 | G4: Max | H4: =IF(G4="Max",C4/E4,IF(G4="Min",(E4-C4)/E4,IF(G4="Opt",(1-ABS(C4-F4)/(E4-F4)),"Fel i logik"))) -> 1 | I4: =H4*D4 -> 0.1
A5: =Indata!A5 -> Rent | B5: =Indata!B5 -> Återvinning | C5: =Indata!C5 -> 300 | D5: 0.1 | E5: 10000 | F5: 3000 | G5: Opt | H5: =IF(G5="Max",C5/E5,IF(G5="Min",(E5-C5)/E5,IF(G5="Opt",(1-ABS(C5-F5)/(E5-F5)),"Fel i logik"))) -> 0.61428571 | I5: =H5*D5 -> 0.061428571
A6: =Indata!A6 -> Möjlighet att mötas | B6: =Indata!B6 -> Torg | C6: =Indata!C6 -> 200 | D6: 0.4 | E6: 10000 | G6: Opt | H6: =IF(G6="Max",C6/E6,IF(G6="Min",(E6-C6)/E6,IF(G6="Opt",(1-ABS(C6-F6)/(E6-F6)),"Fel i logik"))) -> 0.98 | I6: =H6*D6 -> 0.392 | J6: =SUM(I6:I8) -> 0.968 | K6: =A6 -> Möjlighet att mötas
A7: =Indata!A7 -> Möjlighet att mötas | B7: =Indata!B7 -> Park | C7: =Indata!C7 -> 200 | D7: 0.4 | E7: 10000 | G7: Opt | H7: =IF(G7="Max",C7/E7,IF(G7="Min",(E7-C7)/E7,IF(G7="Opt",(1-ABS(C7-F7)/(E7-F7)),"Fel i logik"))) -> 0.98 | I7: =H7*D7 -> 0.392
A8: =Indata!A8 -> Möjlighet att mötas | B8: =Indata!B8 -> Fritidsgård | C8: =Indata!C8 -> 800 | D8: 0.2 | E8: 10000 | G8: Opt | H8: =IF(G8="Max",C8/E8,IF(G8="Min",(E8-C8)/E8,IF(G8="Opt",(1-ABS(C8-F8)/(E8-F8)),"Fel i logik"))) -> 0.92 | I8: =H8*D8 -> 0.184
A9: =Indata!A9 -> Igenkänning | B9: =Indata!B9 -> Nyinflyttning | C9: =Indata!C9 -> 12 | D9: 0.5 | E9: 100 | G9: Min | H9: =IF(G9="Max",C9/E9,IF(G9="Min",(E9-C9)/E9,IF(G9="Opt",(1-ABS(C9-F9)/(E9-F9)),"Fel i logik"))) -> 0.88 | I9: =H9*D9 -> 0.44 | J9: =SUM(I9:I10) -> 0.9 | K9: =A9 -> Igenkänning
A10: =Indata!A10 -> Igenkänning | B10: =Indata!B10 -> Andrahand | C10: =Indata!C10 -> 8 | D10: 0.5 | E10: 100 | G10: Min | H10: =IF(G10="Max",C10/E10,IF(G10="Min",(E10-C10)/E10,IF(G10="Opt",(1-ABS(C10-F10)/(E10-F10)),"Fel i logik"))) -> 0.92 | I10: =H10*D10 -> 0.46
A11: =Indata!A11 -> Trygghet | B11: =Indata!B11 -> Brott | C11: =Indata!C11 -> 45 | D11: 0.7 | E11: 1000 | G11: Min | H11: =IF(G11="Max",C11/E11,IF(G11="Min",(E11-C11)/E11,IF(G11="Opt",(1-ABS(C11-F11)/(E11-F11)),"Fel i logik"))) -> 0.955 | I11: =H11*D11 -> 0.6685 | J11: =SUM(I11:I12) -> 0.8485 | K11: =A11 -> Trygghet
A12: =Indata!A12 -> Trygghet | B12: =Indata!B12 -> Enkät | C12: =Indata!C12 -> 3 | D12: 0.3 | E12: 5 | G12: Max | H12: =IF(G12="Max",C12/E12,IF(G12="Min",(E12-C12)/E12,IF(G12="Opt",(1-ABS(C12-F12)/(E12-F12)),"Fel i logik"))) -> 0.6 | I12: =H12*D12 -> 0.18
A13: =Indata!A13 -> Service | B13: =Indata!B13 -> Post | C13: =Indata!C13 -> 450 | D13: 0.25 | E13: 10000 | F13: 200 | G13: Opt | H13: =IF(G13="Max",C13/E13,IF(G13="Min",(E13-C13)/E13,IF(G13="Opt",(1-ABS(C13-F13)/(E13-F13)),"Fel i logik"))) -> 0.9744898 | I13: =H13*D13 -> 0.24362245 | J13: =SUM(I13:I16) -> 0.95769558 | K13: =A13 -> Service
A14: =Indata!A14 -> Service | B14: =Indata!B14 -> Shopping | C14: =Indata!C14 -> 800 | D14: 0.25 | E14: 10000 | F14: 200 | G14: Opt | H14: =IF(G14="Max",C14/E14,IF(G14="Min",(E14-C14)/E14,IF(G14="Opt",(1-ABS(C14-F14)/(E14-F14)),"Fel i logik"))) -> 0.93877551 | I14: =H14*D14 -> 0.23469388
A15: =Indata!A15 -> Service | B15: =Indata!B15 -> Förskola | C15: =Indata!C15 -> 600 | D15: 0.25 | E15: 10000 | F15: 200 | G15: Opt | H15: =IF(G15="Max",C15/E15,IF(G15="Min",(E15-C15)/E15,IF(G15="Opt",(1-ABS(C15-F15)/(E15-F15)),"Fel i logik"))) -> 0.95918367 | I15: =H15*D15 -> 0.23979592
A16: =Indata!A16 -> Service | B16: =Indata!B16 -> Skola | C16: =Indata!C16 -> 400 | D16: 0.25 | E16: 5000 | F16: 200 | G16: Opt | H16: =IF(G16="Max",C16/E16,IF(G16="Min",(E16-C16)/E16,IF(G16="Opt",(1-ABS(C16-F16)/(E16-F16)),"Fel i logik"))) -> 0.95833333 | I16: =H16*D16 -> 0.23958333
A17: =Indata!A17 -> Utbildning | B17: =Indata!B17 -> Restid | C17: =Indata!C17 -> 45 | D17: 1 | E17: 90 | G17: Min | H17: =IF(G17="Max",C17/E17,IF(G17="Min",(E17-C17)/E17,IF(G17="Opt",(1-ABS(C17-F17)/(E17-F17)),"Fel i logik"))) -> 0.5 | I17: =H17*D17 -> 0.5 | J17: =I17 -> 0.5 | K17: =A17 -> Utbildning
A18: =Indata!A18 -> Barfota | B18: =Indata!B18 -> Grönyta | C18: =Indata!C18 -> 35 | D18: 0.5 | E18: 100 | G18: Max | H18: =IF(G18="Max",C18/E18,IF(G18="Min",(E18-C18)/E18,IF(G18="Opt",(1-ABS(C18-F18)/(E18-F18)),"Fel i logik"))) -> 0.35 | I18: =H18*D18 -> 0.175 | J18: =SUM(I18:I19) -> 0.575 | K18: =A18 -> Barfota
A19: =Indata!A19 -> Barfota | B19: =Indata!B19 -> Kvalitet | C19: =Indata!C19 -> 4 | D19: 0.5 | E19: 5 | G19: Max | H19: =IF(G19="Max",C19/E19,IF(G19="Min",(E19-C19)/E19,IF(G19="Opt",(1-ABS(C19-F19)/(E19-F19)),"Fel i logik"))) -> 0.8 | I19: =H19*D19 -> 0.4
A20: =Indata!A20 -> Föreningsliv | B20: =Indata!B20 -> Avstånd | C20: =Indata!C20 -> 600 | D20: 0.5 | E20: 5000 | F20: 100 | G20: Opt | H20: =IF(G20="Max",C20/E20,IF(G20="Min",(E20-C20)/E20,IF(G20="Opt",(1-ABS(C20-F20)/(E20-F20)),"Fel i logik"))) -> 0.89795918 | I20: =H20*D20 -> 0.44897959 | J20: =SUM(I20:I21) -> 0.87397959 | K20: =A20 -> Föreningsliv
A21: =Indata!A21 -> Föreningsliv | B21: =Indata!B21 -> Antal | C21: =Indata!C21 -> 8 | D21: 0.5 | E21: 100 | F21: 20 | G21: Opt | H21: =IF(G21="Max",C21/E21,IF(G21="Min",(E21-C21)/E21,IF(G21="Opt",(1-ABS(C21-F21)/(E21-F21)),"Fel i logik"))) -> 0.85 | I21: =H21*D21 -> 0.425
A22: =Indata!A22 -> Leveranser | B22: =Indata!B22 -> Täckning | C22: =Indata!C22 -> 8 | D22: 1 | E22: 20 | F22: 10 | G22: Opt | H22: =IF(G22="Max",C22/E22,IF(G22="Min",(E22-C22)/E22,IF(G22="Opt",(1-ABS(C22-F22)/(E22-F22)),"Fel i logik"))) -> 0.8 | I22: =H22*D22 -> 0.8 | J22: =I22 -> 0.8 | K22: =A22 -> Leveranser
A23: =Indata!A23 -> Variation gator | B23: =Indata!B23 -> Gångstråk | C23: =Indata!C23 -> 12 | D23: 1 | E23: 100 | G23: Max | H23: =IF(G23="Max",C23/E23,IF(G23="Min",(E23-C23)/E23,IF(G23="Opt",(1-ABS(C23-F23)/(E23-F23)),"Fel i logik"))) -> 0.12 | I23: =H23*D23 -> 0.12 | J23: =I23 -> 0.12 | K23: =A23 -> Variation gator
A24: =Indata!A24 -> Livsmedel | B24: =Indata!B24 -> Närbutik | C24: 300 | D24: 0.5 | E24: 10000 | F24: 200 | G24: Opt | H24: =IF(G24="Max",C24/E24,IF(G24="Min",(E24-C24)/E24,IF(G24="Opt",(1-ABS(C24-F24)/(E24-F24)),"Fel i logik"))) -> 0.98979592 | I24: =H24*D24 -> 0.49489796 | J24: =SUM(I24:I25) -> 0.90666267 | K24: =A24 -> Livsmedel
A25: =Indata!A25 -> Livsmedel | B25: =Indata!B25 -> Stormarknad | C25: 3000 | D25: 0.5 | E25: 10000 | F25: 1500 | G25: Opt | H25: =IF(G25="Max",C25/E25,IF(G25="Min",(E25-C25)/E25,IF(G25="Opt",(1-ABS(C25-F25)/(E25-F25)),"Fel i logik"))) -> 0.82352941 | I25: =H25*D25 -> 0.41176471
A26: =Indata!A26 -> Kraftmix | B26: =Indata!B26 -> Källor | C26: =Indata!C26 -> 3 | D26: 1 | E26: 10 | G26: Max | H26: =IF(G26="Max",C26/E26,IF(G26="Min",(E26-C26)/E26,IF(G26="Opt",(1-ABS(C26-F26)/(E26-F26)),"Fel i logik"))) -> 0.3 | I26: =H26*D26 -> 0.3 | J26: =I26 -> 0.3 | K26: =A26 -> Kraftmix
A27: =Indata!A27 -> Stress | B27: =Indata!B27 -> Ljudnivå | C27: =Indata!C27 -> 55 | D27: 0.7 | E27: 90 | F27: 50 | G27: Opt | H27: =IF(G27="Max",C27/E27,IF(G27="Min",(E27-C27)/E27,IF(G27="Opt",(1-ABS(C27-F27)/(E27-F27)),"Fel i logik"))) -> 0.875 | I27: =H27*D27 -> 0.6125 | J27: =SUM(I27:I28) -> 0.8125 | K27: =A27 -> Stress
A28: Stress | B28: Fordonshastighet | C28: =Indata!C28 -> 40 | D28: 0.3 | E28: 120 | G28: Min | H28: =IF(G28="Max",C28/E28,IF(G28="Min",(E28-C28)/E28,IF(G28="Opt",(1-ABS(C28-F28)/(E28-F28)),"Fel i logik"))) -> 0.66666667 | I28: =H28*D28 -> 0.2
A29: =Indata!A29 -> Levande bottenvån | B29: =Indata!B29 -> Kommersiell yta | C29: =Indata!C29 -> 3 | D29: 1 | E29: 100 | G29: Max | H29: =IF(G29="Max",C29/E29,IF(G29="Min",(E29-C29)/E29,IF(G29="Opt",(1-ABS(C29-F29)/(E29-F29)),"Fel i logik"))) -> 0.03 | I29: =H29*D29 -> 0.03 | J29: =I29 -> 0.03 | K29: =A29 -> Levande bottenvån
A30: =Indata!A30 -> Spontanidrott | B30: =Indata!B30 -> Yta upp till 200m | C30: =Indata!C30 -> 2 | D30: 0.4 | E30: 10 | F30: 5 | G30: Max | H30: =IF(G30="Max",C30/E30,IF(G30="Min",(E30-C30)/E30,IF(G30="Opt",(1-ABS(C30-F30)/(E30-F30)),"Fel i logik"))) -> 0.2 | I30: =H30*D30 -> 0.08 | J30: =SUM(I30:I32) -> 0.2 | K30: =A30 -> Spontanidrott
A31: =Indata!A31 -> Spontanidrott | B31: =Indata!B31 -> Yta upp till500m | C31: =Indata!C31 -> 1 | D31: 0.3 | E31: 10 | F31: 5 | G31: Max | H31: =IF(G31="Max",C31/E31,IF(G31="Min",(E31-C31)/E31,IF(G31="Opt",(1-ABS(C31-F31)/(E31-F31)),"Fel i logik"))) -> 0.1 | I31: =H31*D31 -> 0.03
A32: =Indata!A32 -> Spontanidrott | B32: =Indata!B32 -> Yta 1000m eller större | C32: =Indata!C32 -> 3 | D32: 0.3 | E32: 10 | F32: 5 | G32: Max | H32: =IF(G32="Max",C32/E32,IF(G32="Min",(E32-C32)/E32,IF(G32="Opt",(1-ABS(C32-F32)/(E32-F32)),"Fel i logik"))) -> 0.3 | I32: =H32*D32 -> 0.09
A33: =Indata!A33 -> Restauranger | B33: =Indata!B33 -> Transporttid | C33: =Indata!C33 -> 8 | D33: 1 | E33: 60 | G33: Min | H33: =IF(G33="Max",C33/E33,IF(G33="Min",(E33-C33)/E33,IF(G33="Opt",(1-ABS(C33-F33)/(E33-F33)),"Fel i logik"))) -> 0.86666667 | I33: =H33*D33 -> 0.86666667 | J33: =I33 -> 0.86666667 | K33: =A33 -> Restauranger
A34: =Indata!A34 -> Vänlighet | B34: =Indata!B34 -> Enkät | C34: =Indata!C34 -> 5 | D34: 0.5 | E34: 5 | G34: Max | H34: =IF(G34="Max",C34/E34,IF(G34="Min",(E34-C34)/E34,IF(G34="Opt",(1-ABS(C34-F34)/(E34-F34)),"Fel i logik"))) -> 1 | I34: =H34*D34 -> 0.5 | J34: =SUM(I34:I35) -> 0.96 | K34: =A34 -> Vänlighet
A35: =Indata!A35 -> Vänlighet | B35: =Indata!B35 -> Omsättning | C35: =Indata!C35 -> 8 | D35: 0.5 | E35: 100 | G35: Min | H35: =IF(G35="Max",C35/E35,IF(G35="Min",(E35-C35)/E35,IF(G35="Opt",(1-ABS(C35-F35)/(E35-F35)),"Fel i logik"))) -> 0.92 | I35: =H35*D35 -> 0.46
A36: =Indata!A36 -> Respekt | B36: =Indata!B36 -> Ålder | C36: =Indata!C36 -> 40 | D36: 0.25 | E36: 100 | G36: Max | H36: =IF(G36="Max",C36/E36,IF(G36="Min",(E36-C36)/E36,IF(G36="Opt",(1-ABS(C36-F36)/(E36-F36)),"Fel i logik"))) -> 0.4 | I36: =H36*D36 -> 0.1 | J36: =SUM(I36:I39) -> 0.605 | K36: =A36 -> Respekt
A37: =Indata!A37 -> Respekt | B37: =Indata!B37 -> Hushåll | C37: =Indata!C37 -> 3 | D37: 0.25 | E37: 6 | G37: Max | H37: =IF(G37="Max",C37/E37,IF(G37="Min",(E37-C37)/E37,IF(G37="Opt",(1-ABS(C37-F37)/(E37-F37)),"Fel i logik"))) -> 0.5 | I37: =H37*D37 -> 0.125
A38: =Indata!A38 -> Respekt | B38: =Indata!B38 -> Bostadsform | C38: =Indata!C38 -> 5 | D38: 0.3 | E38: 5 | G38: Max | H38: =IF(G38="Max",C38/E38,IF(G38="Min",(E38-C38)/E38,IF(G38="Opt",(1-ABS(C38-F38)/(E38-F38)),"Fel i logik"))) -> 1 | I38: =H38*D38 -> 0.3
A39: =Indata!A39 -> Respekt | B39: =Indata!B39 -> Inkomst | C39: =Indata!C39 -> 2 | D39: 0.2 | E39: 5 | G39: Max | H39: =IF(G39="Max",C39/E39,IF(G39="Min",(E39-C39)/E39,IF(G39="Opt",(1-ABS(C39-F39)/(E39-F39)),"Fel i logik"))) -> 0.4 | I39: =H39*D39 -> 0.08
A40: =Indata!A40 -> Inomhussport | B40: =Indata!B40 -> Simhall | C40: =Indata!C40 -> 3000 | D40: 0.4 | E40: 10000 | F40: 500 | G40: Opt | H40: =IF(G40="Max",C40/E40,IF(G40="Min",(E40-C40)/E40,IF(G40="Opt",(1-ABS(C40-F40)/(E40-F40)),"Fel i logik"))) -> 0.73684211 | I40: =H40*D40 -> 0.29473684 | J40: =SUM(I40:I41) -> 0.8 | K40: =A40 -> Inomhussport
...

Sheet Resultat
A1: =Definitioner!A4 -> Parameter | B1: Resultat | C1: Maxpoäng
A2: =Definitioner!A5 -> Rent | B2: =_xlfn.XLOOKUP(A2,Beräkningar!K:K,Beräkningar!J:J,"Fel") -> 0.75571429 | C2: 1
A3: =Definitioner!A6 -> Möjlighet att mötas | B3: =_xlfn.XLOOKUP(A3,Beräkningar!K:K,Beräkningar!J:J,"Fel") -> 0.968 | C3: 1
A4: =Definitioner!A7 -> Igenkänning | B4: =_xlfn.XLOOKUP(A4,Beräkningar!K:K,Beräkningar!J:J,"Fel") -> 0.9 | C4: 1
A5: =Definitioner!A8 -> Trygghet | B5: =_xlfn.XLOOKUP(A5,Beräkningar!K:K,Beräkningar!J:J,"Fel") -> 0.8485 | C5: 1
A6: =Definitioner!A9 -> Service | B6: =_xlfn.XLOOKUP(A6,Beräkningar!K:K,Beräkningar!J:J,"Fel") -> 0.95769558 | C6: 1
A7: =Definitioner!A10 -> Utbildning | B7: =_xlfn.XLOOKUP(A7,Beräkningar!K:K,Beräkningar!J:J,"Fel") -> 0.5 | C7: 1
A8: =Definitioner!A11 -> Barfota | B8: =_xlfn.XLOOKUP(A8,Beräkningar!K:K,Beräkningar!J:J,"Fel") -> 0.575 | C8: 1
A9: =Definitioner!A12 -> Föreningsliv | B9: =_xlfn.XLOOKUP(A9,Beräkningar!K:K,Beräkningar!J:J,"Fel") -> 0.87397959 | C9: 1
A10: =Definitioner!A13 -> Leveranser | B10: =_xlfn.XLOOKUP(A10,Beräkningar!K:K,Beräkningar!J:J,"Fel") -> 0.8 | C10: 1
A11: =Definitioner!A14 -> Variation gator | B11: =_xlfn.XLOOKUP(A11,Beräkningar!K:K,Beräkningar!J:J,"Fel") -> 0.12 | C11: 1
A12: =Definitioner!A15 -> Livsmedel | B12: =_xlfn.XLOOKUP(A12,Beräkningar!K:K,Beräkningar!J:J,"Fel") -> 0.90666267 | C12: 1
A13: =Definitioner!A16 -> Kraftmix | B13: =_xlfn.XLOOKUP(A13,Beräkningar!K:K,Beräkningar!J:J,"Fel") -> 0.3 | C13: 1
... A31: =Definitioner!A34 -> Blandad bebyggelse | B31: =_xlfn.XLOOKUP(A31,Beräkningar!K:K,Beräkningar!J:J,"Fel") -> 0.66666667 | C31: 1
A32: =Definitioner!A35 -> 0
